Workbook

Sheet 宝
A1: |-编号---- | B1: |-英文---- | C1: |-日文---- | D1: |-翻译---- | E1: |-注释---- | F1: |-跳过---- | G1: |-拼音- | H1: |-拼音2- | I1: |-拼音3- | J1: |-拼音4- | K1: |-拼音5-
A2: N001 | B2: BULBASAUR | C2: フシギダネ | D2: 妙蛙种子 | G2: miao4 | H2: wa1 | I2: zhong3 | J2: zi
A3: N002 | B3: IVYSAUR | C3: フシギソウ | D3: 妙蛙草 | G3: miao4 | H3: wa1 | I3: cao3
A4: N003 | B4: VENUSAUR | C4: フシギバナ | D4: 妙蛙花 | G4: miao4 | H4: wa1 | I4: hua1
A5: N004 | B5: CHARMANDER | C5: ヒトカゲ | D5: 小火龙 | G5: xiao3 | H5: huo3 | I5: long2
A6: N005 | B6: CHARMELEON | C6: リザード | D6: 火恐龙 | G6: huo3 | H6: kong3 | I6: long2
A7: N006 | B7: CHARIZARD | C7: リザードン | D7: 喷火龙 | G7: pen1 | H7: huo3 | I7: long2
A8: N007 | B8: SQUIRTLE | C8: ゼニガメ | D8: 杰尼龟 | G8: jie2 | H8: ni2 | I8: gui1
A9: N008 | B9: WARTORTLE | C9: カメール | D9: 卡咪龟 | G9: ka3 | H9: mi1 | I9: gui1
A10: N009 | B10: BLASTOISE | C10: カメックス | D10: 水箭龟 | G10: shui3 | H10: jian4 | I10: gui1
A11: N010 | B11: CATERPIE | C11: キャタピー | D11: 绿毛虫 | G11: lv4 | H11: mao2 | I11: chong2
A12: N011 | B12: METAPOD | C12: トランセル | D12: 铁甲蛹 | G12: tie3 | H12: jia3 | I12: yong3
A13: N012 | B13: BUTTERFREE | C13: バタフリー | D13: 巴大蝶 | G13: ba1 | H13: da4 | I13: die2
A14: N013 | B14: WEEDLE | C14: ビードル | D14: 独角虫 | G14: du2 | H14: jiao3 | I14: chong2
... A16: N015 | B16: BEEDRILL | C16: スピアー | D16: 大针蜂 | G16: da4 | H16: zhen1 | I16: feng1
A17: N016 | B17: PIDGEY | C17: ポッポ | D17: 波波 | G17: bo1 | H17: bo1
A18: N017 | B18: PIDGEOTTO | C18: ピジョン | D18: 比比鸟 | G18: bi3 | H18: bi3 | I18: niao3
A19: N018 | B19: PIDGEOT | C19: ピジョット | D19: 大比鸟 | G19: da4 | H19: bi3 | I19: niao3
A20: N019 | B20: RATTATA | C20: コラッタ | D20: 小拉达 | G20: xiao3 | H20: la1 | I20: da2
A21: N020 | B21: RATICATE | C21: ラッタ | D21: 拉达 | G21: la1 | H21: da2
A22: N021 | B22: SPEAROW | C22: オニスズメ | D22: 烈雀 | G22: lie4 | H22: que4
A23: N022 | B23: FEAROW | C23: オニドリル | D23: 大嘴雀 | G23: da4 | H23: zui3 | I23: que4
A24: N023 | B24: EKANS | C24: アーボ | D24: 阿柏蛇 | G24: a1 | H24: bo2 | I24: she2
A25: N024 | B25: ARBOK | C25: アーボック | D25: 阿柏怪 | G25: a1 | H25: bo2 | I25: guai4
A26: N025 | B26: PIKACHU | C26: ピカチュウ | D26: 皮卡丘 | G26: pi2 | H26: ka3 | I26: qiu1
A27: N026 | B27: RAICHU | C27: ライチュウ | D27: 雷丘 | G27: lei2 | H27: qiu1
A28: N027 | B28: SANDSHREW | C28: サンド | D28: 穿山鼠 | G28: chuan1 | H28: shan1 | I28: shu3
A29: N028 | B29: SANDSLASH | C29: サンドパン | D29: 穿山王 | G29: chuan1 | H29: shan1 | I29: wang2
A30: N029 | B30: NIDORAN♀ | C30: ニドラン♀ | D30: 尼多兰 | G30: ni2 | H30: duo1 | I30: lan2
A31: N030 | B31: NIDORINA | C31: ニドリーナ | D31: 尼多娜 | G31: ni2 | H31: duo1 | I31: na4
A32: N031 | B32: NIDOQUEEN | C32: ニドクイン | D32: 尼多后 | G32: ni2 | H32: duo1 | I32: hou4
A33: N032 | B33: NIDORAN♂ | C33: ニドラン♂ | D33: 尼多朗 | G33: ni2 | H33: duo1 | I33: lang3
A34: N033 | B34: NIDORINO | C34: ニドリーノ | D34: 尼多力诺 | G34: ni2 | H34: duo1 | I34: li4 | J34: nuo4
A35: N034 | B35: NIDOKING | C35: ニドキング | D35: 尼多王 | G35: ni2 | H35: duo1 | I35: wang2
A36: N035 | B36: CLEFAIRY | C36: ピッピ | D36: 皮皮 | G36: pi2 | H36: pi2
A37: N036 | B37: CLEFABLE | C37: ピクシー | D37: 皮可西 | G37: pi2 | H37: ke3 | I37: xi1
A38: N037 | B38: VULPIX | C38: ロコン | D38: 六尾 | G38: liu4 | H38: wei3
A39: N038 | B39: NINETALES | C39: キュウコン | D39: 九尾 | G39: jiu3 | H39: wei3
A40: N039 | B40: JIGGLYPUFF | C40: プリン | D40: 胖丁 | G40: pang4 | H40: ding1
A41: N040 | B41: WIGGLYTUFF | C41: プクリン | D41: 胖可丁 | G41: pang4 | H41: ke3 | I41: ding1
...

Sheet 训
A1: |-编号---- | B1: |-英文---- | C1: |-日文---- | D1: |-翻译---- | E1: |-注释---- | F1: |-跳过---- | G1: 版本
A2: P2DL_001$ | B2: FALKNER | C2: ハヤト | D2: 阿速 | H2: FALKNER
A3: P2DL_002$ | B3: WHITNEY | C3: アカネ | D3: 小茜 | H3: WHITNEY
A4: P2DL_003$ | B4: BUGSY | C4: ツクシ | D4: 阿笔 | H4: BUGSY
A5: P2DL_004$ | B5: MORTY | C5: マツバ | D5: 松叶 | H5: MORTY
A6: P2DL_005$ | B6: PRYCE | C6: ヤナギ | D6: 柳伯 | H6: PRYCE
A7: P2DL_006$ | B7: JASMINE | C7: ミカン | D7: 阿蜜 | H7: JASMINE
A8: P2DL_007$ | B8: CHUCK | C8: シジマ | D8: 阿四 | H8: CHUCK
A9: P2DL_008$ | B9: CLAIR | C9: イブキ | D9: 小椿 | H9: CLAIR
A10: P2DL_009$ | B10: ? | C10: ? | D10: ? | E10: 没用的符号，忽略 | F10: Y | H10: ?
A11: P2DL_009_00$ | B11: =B10 -> ? | C11: =C10 -> ? | D11: =D10 -> ? | H11: ?
A12: P2DL_009_01$ | B12: =B10 -> ? | C12: =C10 -> ? | D12: =D10 -> ? | H12: ?
A13: P2DL_009_02$ | B13: =B10 -> ? | C13: =C10 -> ? | D13: =D10 -> ? | H13: ?
A14: P2DL_009_03$ | B14: =B10 -> ? | C14: =C10 -> ? | D14: =D10 -> ? | H14: ?
A15: P2DL_009_04$ | B15: =B10 -> ? | C15: =C10 -> ? | D15: =D10 -> ? | H15: ?
A16: P2DL_009_05$ | B16: =B10 -> ? | C16: =C10 -> ? | D16: =D10 -> ? | H16: ?
A17: P2DL_009_06$ | B17: =B10 -> ? | C17: =C10 -> ? | D17: =D10 -> ? | H17: ?
A18: P2DL_009_07$ | B18: =B10 -> ? | C18: =C10 -> ? | D18: =D10 -> ? | H18: ?
A19: P2DL_009_08$ | B19: =B10 -> ? | C19: =C10 -> ? | D19: =D10 -> ? | H19: ?
A20: P2DL_009_09$ | B20: =B10 -> ? | C20: =C10 -> ? | D20: =D10 -> ? | H20: ?
A21: P2DL_009_10$ | B21: =B10 -> ? | C21: =C10 -> ? | D21: =D10 -> ? | H21: ?
A22: P2DL_009_11$ | B22: =B10 -> ? | C22: =C10 -> ? | D22: =D10 -> ? | H22: ?
A23: P2DL_009_12$ | B23: =B10 -> ? | C23: =C10 -> ? | D23: =D10 -> ? | H23: ?
A24: P2DL_009_13$ | B24: =B10 -> ? | C24: =C10 -> ? | D24: =D10 -> ? | H24: ?
A25: P2DL_011$ | B25: WILL | C25: イツキ | D25: 一树 | H25: WILL
A26: P2DL_012$ | B26: CAL | C26: ヒカル | D26: 光亮 | E26: 主角克隆 | H26: CAL
A27: P2DL_012_00$ | B27: =B26 -> CAL | C27: =C26 -> ヒカル | D27: =D26 -> 光亮 | H27: CAL
A28: P2DL_012_01$ | B28: =B26 -> CAL | C28: =C26 -> ヒカル | D28: =D26 -> 光亮 | H28: CAL
A29: P2DL_013$ | B29: BRUNO | C29: シバ | D29: 希巴 | H29: BRUNO
A30: P2DL_014$ | B30: KAREN | C30: カリン | D30: 梨花 | H30: KAREN
A31: P2DL_015$ | B31: KOGA | C31: キョウ | D31: 阿桔 | H31: KOGA
A32: P2DL_016$ | B32: LANCE | C32: ワタル | D32: 阿渡 | H32: LANCE
A33: P2DL_017$ | B33: BROCK | C33: タケシ | D33: 小刚 | H33: BROCK
A34: P2DL_018$ | B34: MISTY | C34: カスミ | D34: 小霞 | H34: MISTY
A35: P2DL_019$ | B35: LT.SURGE | C35: マチス | D35: 马志士 | H35: LT.SURGE
A36: P2DL_020$ | B36: ROSS | C36: ヤスフミ | D36: 康文 | H36: ROSS
A37: P2DL_020_00$ | B37: MITCH | C37: ノブヒロ | D37: 信弘 | H37: MITCH
A38: P2DL_020_01$ | B38: JED | C38: フジオ | D38: 不二雄 | H38: JED
A39: P2DL_020_02$ | B39: MARC | C39: カネオ | D39: 兼生 | H39: MARC
A40: P2DL_020_03$ | B40: RICH | C40: シンタロウ | D40: 真太郎 | H40: RICH
...

Sheet 类
A1: |-编号---- | B1: |-英文---- | C1: |-日文---- | D1: |-翻译---- | E1: |-注释---- | F1: |-跳过----
A2: Name_P2DL_001$ | B2: LEADER | C2: ジムリーダー | D2: 道馆馆主
A3: Name_P2DL_002$ | B3: =B2 -> LEADER | C3: =C2 -> ジムリーダー | D3: =D2 -> 道馆馆主
A4: Name_P2DL_003$ | B4: =B2 -> LEADER | C4: =C2 -> ジムリーダー | D4: =D2 -> 道馆馆主
A5: Name_P2DL_004$ | B5: =B2 -> LEADER | C5: =C2 -> ジムリーダー | D5: =D2 -> 道馆馆主
A6: Name_P2DL_005$ | B6: =B2 -> LEADER | C6: =C2 -> ジムリーダー | D6: =D2 -> 道馆馆主
A7: Name_P2DL_006$ | B7: =B2 -> LEADER | C7: =C2 -> ジムリーダー | D7: =D2 -> 道馆馆主
A8: Name_P2DL_007$ | B8: =B2 -> LEADER | C8: =C2 -> ジムリーダー | D8: =D2 -> 道馆馆主
A9: Name_P2DL_008$ | B9: =B2 -> LEADER | C9: =C2 -> ジムリーダー | D9: =D2 -> 道馆馆主
A10: Name_P2DL_009$ | B10: RIVAL | C10: ライバル | D10: 劲敌
A11: Name_P2DL_010$ | B11: #MON PROF. | C11: ポケモンはかせ | D11: 宝可梦博士
A12: Name_P2DL_011$ | B12: ELITE FOUR | C12: してんのう | D12: 四天王
A13: Name_P2DL_012$ | B13: <PKMN> TRAINER | C13: ポケモントレーナー | D13: 宝可梦训练家
A14: Name_P2DL_013$ | B14: =B12 -> ELITE FOUR | C14: =C12 -> してんのう | D14: =D12 -> 四天王
A15: Name_P2DL_014$ | B15: =B12 -> ELITE FOUR | C15: =C12 -> してんのう | D15: =D12 -> 四天王
A16: Name_P2DL_015$ | B16: =B12 -> ELITE FOUR | C16: =C12 -> してんのう | D16: =D12 -> 四天王
A17: Name_P2DL_016$ | B17: CHAMPION | C17: チャンピオン | D17: 冠军
A18: Name_P2DL_017$ | B18: =B2 -> LEADER | C18: =C2 -> ジムリーダー | D18: =D2 -> 道馆馆主
A19: Name_P2DL_018$ | B19: =B2 -> LEADER | C19: =C2 -> ジムリーダー | D19: =D2 -> 道馆馆主
A20: Name_P2DL_019$ | B20: =B2 -> LEADER | C20: =C2 -> ジムリーダー | D20: =D2 -> 道馆馆主
A21: Name_P2DL_020$ | B21: SCIENTIST | C21: はぐれけんきゅういん | D21: 流浪研究员
A22: Name_P2DL_021$ | B22: =B2 -> LEADER | C22: =C2 -> ジムリーダー | D22: =D2 -> 道馆馆主
A23: Name_P2DL_022$ | B23: YOUNGSTER | C23: たんパンこぞう | D23: 短裤小子
A24: Name_P2DL_023$ | B24: SCHOOLBOY | C24: じゅくがえり | D24: 补习班学生
A25: Name_P2DL_024$ | B25: BIRD KEEPER | C25: とりつかい | D25: 养鸟人
A26: Name_P2DL_025$ | B26: LASS | C26: ミニスカート | D26: 迷你裙
A27: Name_P2DL_026$ | B27: =B2 -> LEADER | C27: =C2 -> ジムリーダー | D27: =D2 -> 道馆馆主
A28: Name_P2DL_027$ | B28: COOLTRAINER | C28: エリートトレーナー | D28: 精英训练家
A29: Name_P2DL_028$ | B29: =B28 -> COOLTRAINER | C29: =C28 -> エリートトレーナー | D29: =D28 -> 精英训练家
A30: Name_P2DL_029$ | B30: BEAUTY | C30: おとなのおねえさん | D30: 大姐姐
A31: Name_P2DL_030$ | B31: #MANIAC | C31: かいじゅうマニア | D31: 怪兽狂
A32: Name_P2DL_031$ | B32: ROCKET | C32: ロケットだんいん | D32: 火箭队员
A33: Name_P2DL_032$ | B33: GENTLEMAN | C33: ジェントルマン | D33: 绅士
A34: Name_P2DL_033$ | B34: SKIER | C34: スキーヤー | D34: 滑雪者
A35: Name_P2DL_034$ | B35: TEACHER | C35: せんせい | D35: 老师
A36: Name_P2DL_035$ | B36: =B2 -> LEADER | C36: =C2 -> ジムリーダー | D36: =D2 -> 道馆馆主
A37: Name_P2DL_036$ | B37: BUG CATCHER | C37: むしとり | D37: 捕虫少年
A38: Name_P2DL_037$ | B38: FISHER | C38: つりびと | D38: 垂钓者
A39: Name_P2DL_038$ | B39: SWIMMER♂ | C39: かいパンやろう | D39: 泳裤小伙子
A40: Name_P2DL_039$ | B40: SWIMMER♀ | C40: ビキニのおねえさん | D40: 比基尼姐姐
...

Sheet 城
A1: |-编号---- | B1: |-英文---- | C1: |-日文---- | D1: |-翻译---- | E1: |-注释---- | F1: |-跳过----
A2: name_wakaba | B2: NEW BARK TOWN | C2: ワカバタウン | D2: 若叶镇
A3: name_yosino | B3: CHERRYGROVE CITY | C3: ヨシノシティ | D3: 吉花市
A4: name_kikyou | B4: VIOLET CITY | C4: キキョウシティ | D4: 桔梗市
A5: name_hiwada | B5: AZALEA TOWN | C5: ヒワダタウン | D5: 桧皮镇
A6: name_kogane | B6: GOLDENROD CITY | C6: コガネシティ | D6: 满金市
A7: name_enjyu | B7: ECRUTEAK CITY | C7: エンジュシティ | D7: 缘朱市
A8: name_asagi | B8: OLIVINE CITY | C8: アサギシティ | D8: 浅葱市
A9: name_tanba | B9: CIANWOOD CITY | C9: タンバシティ | D9: 湛蓝市
A10: name_tyouji | B10: MAHOGANY TOWN | C10: チョウジタウン | D10: 卡吉镇
A11: name_fusube | B11: BLACKTHORN CITY | C11: フスベシティ | D11: 烟墨市
A12: name_ikari | B12: LAKE OF RAGE | C12: いかりのみずうみ | D12: 愤怒之湖
A13: name_sirogane | B13: SILVER CAVE | C13: シロガネやま | D13: 白银山
... A103: name_special | B103: SPECIAL | C103: スペシャル(???) | D103: 特别(???)

Sheet 城GS
A1: |-编号---- | B1: |-英文---- | C1: |-日文---- | D1: |-翻译---- | E1: |-注释---- | F1: |-跳过----
A2: name_wakaba | B2: NEW BARK TOWN | C2: ワカバタウン | D2: 若叶镇
A3: name_yosino | B3: CHERRYGROVE CITY | C3: ヨシノシティ | D3: 吉花市
A4: name_kikyou | B4: VIOLET CITY | C4: キキョウシティ | D4: 桔梗市
A5: name_hiwada | B5: AZALEA TOWN | C5: ヒワダタウン | D5: 桧皮镇
A6: name_kogane | B6: GOLDENROD CITY | C6: コガネシティ | D6: 满金市
A7: name_enjyu | B7: ECRUTEAK CITY | C7: エンジュシティ | D7: 缘朱市
A8: name_asagi | B8: OLIVINE CITY | C8: アサギシティ | D8: 浅葱市
A9: name_tanba | B9: CIANWOOD CITY | C9: タンバシティ | D9: 湛蓝市
A10: name_tyouji | B10: MAHOGANY TOWN | C10: チョウジタウン | D10: 卡吉镇
A11: name_fusube | B11: BLACKTHORN CITY | C11: フスベシティ | D11: 烟墨市
A12: name_ikari | B12: LAKE OF RAGE | C12: いかりのみずうみ | D12: 愤怒之湖
A13: name_sirogane | B13: SILVER CAVE | C13: シロガネやま | D13: 白银山
... A103: name_special | B103: SPECIAL | C103: スペシャル(???) | D103: 特别(???)

Sheet 道
A1: |-编号---- | B1: |-英文---- | C1: |-日文---- | D1: |-翻译---- | E1: |-注释---- | F1: |-跳过----
A2: ItemName001$ | B2: MASTER BALL | C2: マスターボール | D2: 大师球
A3: ItemName002$ | B3: ULTRA BALL | C3: ハイパーボール | D3: 高级球
A4: ItemName003$ | B4: BRIGHTPOWDER | C4: ひかりのこな | D4: 光粉
A5: ItemName004$ | B5: GREAT BALL | C5: スーパーボール | D5: 超级球
A6: ItemName005$ | B6: # BALL | C6: モンスターボール | D6: 精灵球
A7: ItemName006$ | B7: TERU-SAMA | C7: カビチュウ | D7: 卡比丘
A8: ItemName007$ | B8: BICYCLE | C8: じてんしゃ | D8: 自行车
A9: ItemName008$ | B9: MOON STONE | C9: つきのいし | D9: 月之石
A10: ItemName009$ | B10: ANTIDOTE | C10: どくけし | D10: 解毒药
A11: ItemName010$ | B11: BURN HEAL | C11: やけどなおし | D11: 灼伤药
A12: ItemName011$ | B12: ICE HEAL | C12: こおりなおし | D12: 解冻药
A13: ItemName012$ | B13: AWAKENING | C13: ねむけざまし | D13: 解眠药
... A21: ItemName020$ | B21: REPEL | C21: むしよけスプレー | D21: 除虫喷雾
A22: ItemName021$ | B22: MAX ELIXER | C22: ピーピーマックス | D22: PP多项全补剂 | E22: 太长的名字，游戏各处需要补丁。
A23: ItemName022$ | B23: FIRE STONE | C23: ほのおのいし | D23: 火之石
A24: ItemName023$ | B24: THUNDERSTONE | C24: かみなりのいし | D24: 雷之石
A25: ItemName024$ | B25: WATER STONE | C25: みずのいし | D25: 水之石
A26: ItemName025$ | B26: =B7 -> TERU-SAMA | C26: =C7 -> カビチュウ | D26: =D7 -> 卡比丘
A27: ItemName026$ | B27: HP UP | C27: マックスアップ | D27: HP增强剂
A28: ItemName027$ | B28: PROTEIN | C28: タウリン | D28: 攻击增强剂
A29: ItemName028$ | B29: IRON | C29: ブロムヘキシン | D29: 防御增强剂
A30: ItemName029$ | B30: CARBOS | C30: インドメタシン | D30: 速度增强剂
A31: ItemName030$ | B31: LUCKY PUNCH | C31: ラッキーパンチ | D31: 吉利拳
A32: ItemName031$ | B32: CALCIUM | C32: リゾチウム | D32: 特殊增强剂
A33: ItemName032$ | B33: RARE CANDY | C33: ふしぎなアメ | D33: 神奇糖果
A34: ItemName033$ | B34: X ACCURACY | C34: ヨクアタール | D34: 命中强化
A35: ItemName034$ | B35: LEAF STONE | C35: リーフのいし | D35: 叶之石
A36: ItemName035$ | B36: METAL POWDER | C36: メタルパウダー | D36: 金属粉
A37: ItemName036$ | B37: NUGGET | C37: きんのたま | D37: 金珠
A38: ItemName037$ | B38: # DOLL | C38: ピッピにんぎょう | D38: 皮皮玩偶
... A45: ItemName044$ | B45: DIRE HIT | C45: クリティカッター | D45: 要害攻击
A46: ItemName045$ | B46: =B7 -> TERU-SAMA | C46: =C7 -> カビチュウ | D46: =D7 -> 卡比丘
A47: ItemName046$ | B47: FRESH WATER | C47: おいしいみず | D47: 美味之水
A48: ItemName047$ | B48: SODA POP | C48: サイコソーダ | D48: 劲爽汽水
A49: ItemName048$ | B49: LEMONADE | C49: ミックスオレ | D49: 果汁牛奶
A50: ItemName049$ | B50: X ATTACK | C50: プラスパワー | D50: 力量强化
A51: ItemName050$ | B51: =B7 -> TERU-SAMA | C51: =C7 -> カビチュウ | D51: =D7 -> 卡比丘
A52: ItemName051$ | B52: X DEFEND | C52: ディフェンダー | D52: 防御强化
A53: ItemName052$ | B53: X SPEED | C53: スピーダー | D53: 速度强化
...

Sheet 道GS
A1: |-编号---- | B1: |-英文---- | C1: |-日文---- | D1: |-翻译---- | E1: |-注释---- | F1: |-跳过----
A2: ItemName001$ | B2: MASTER BALL | C2: マスターボール | D2: 大师球
A3: ItemName002$ | B3: ULTRA BALL | C3: ハイパーボール | D3: 高级球
A4: ItemName003$ | B4: BRIGHTPOWDER | C4: ひかりのこな | D4: 光粉
A5: ItemName004$ | B5: GREAT BALL | C5: スーパーボール | D5: 超级球
A6: ItemName005$ | B6: # BALL | C6: モンスターボール | D6: 精灵球
A7: ItemName006$ | B7: TERU-SAMA | C7: カビチュウ | D7: 卡比丘
A8: ItemName007$ | B8: BICYCLE | C8: じてんしゃ | D8: 自行车
A9: ItemName008$ | B9: MOON STONE | C9: つきのいし | D9: 月之石
A10: ItemName009$ | B10: ANTIDOTE | C10: どくけし | D10: 解毒药
A11: ItemName010$ | B11: BURN HEAL | C11: やけどなおし | D11: 灼伤药
A12: ItemName011$ | B12: ICE HEAL | C12: こおりなおし | D12: 解冻药
A13: ItemName012$ | B13: AWAKENING | C13: ねむけざまし | D13: 解眠药
... A21: ItemName020$ | B21: REPEL | C21: むしよけスプレー | D21: 除虫喷雾
A22: ItemName021$ | B22: MAX ELIXER | C22: ピーピーマックス | D22: PP多项全补剂 | E22: 太长的名字，游戏各处需要补丁。
A23: ItemName022$ | B23: FIRE STONE | C23: ほのおのいし | D23: 火之石
A24: ItemName023$ | B24: THUNDERSTONE | C24: かみなりのいし | D24: 雷之石
A25: ItemName024$ | B25: WATER STONE | C25: みずのいし | D25: 水之石
A26: ItemName025$ | B26: =B7 -> TERU-SAMA | C26: =C7 -> カビチュウ | D26: =D7 -> 卡比丘
A27: ItemName026$ | B27: HP UP | C27: マックスアップ | D27: HP增强剂
A28: ItemName027$ | B28: PROTEIN | C28: タウリン | D28: 攻击增强剂
A29: ItemName028$ | B29: IRON | C29: ブロムヘキシン | D29: 防御增强剂
A30: ItemName029$ | B30: CARBOS | C30: インドメタシン | D30: 速度增强剂
A31: ItemName030$ | B31: LUCKY PUNCH | C31: ラッキーパンチ | D31: 吉利拳
A32: ItemName031$ | B32: CALCIUM | C32: リゾチウム | D32: 特殊增强剂
A33: ItemName032$ | B33: RARE CANDY | C33: ふしぎなアメ | D33: 神奇糖果
A34: ItemName033$ | B34: X ACCURACY | C34: ヨクアタール | D34: 命中强化
A35: ItemName034$ | B35: LEAF STONE | C35: リーフのいし | D35: 叶之石
A36: ItemName035$ | B36: METAL POWDER | C36: メタルパウダー | D36: 金属粉
A37: ItemName036$ | B37: NUGGET | C37: きんのたま | D37: 金珠
A38: ItemName037$ | B38: # DOLL | C38: ピッピにんぎょう | D38: 皮皮玩偶
... A45: ItemName044$ | B45: DIRE HIT | C45: クリティカッター | D45: 要害攻击
A46: ItemName045$ | B46: =B7 -> TERU-SAMA | C46: =C7 -> カビチュウ | D46: =D7 -> 卡比丘
A47: ItemName046$ | B47: FRESH WATER | C47: おいしいみず | D47: 美味之水
A48: ItemName047$ | B48: SODA POP | C48: サイコソーダ | D48: 劲爽汽水
A49: ItemName048$ | B49: LEMONADE | C49: ミックスオレ | D49: 果汁牛奶
A50: ItemName049$ | B50: X ATTACK | C50: プラスパワー | D50: 力量强化
A51: ItemName050$ | B51: =B7 -> TERU-SAMA | C51: =C7 -> カビチュウ | D51: =D7 -> 卡比丘
A52: ItemName051$ | B52: X DEFEND | C52: ディフェンダー | D52: 防御强化
A53: ItemName052$ | B53: X SPEED | C53: スピーダー | D53: 速度强化
...

Sheet 招
A1: |-编号---- | B1: |-英文---- | C1: |-日文---- | D1: |-翻译---- | E1: |-注释---- | F1: |-跳过----
A2: M001 | B2: POUND | C2: はたく | D2: 拍击
A3: M002 | B3: KARATE CHOP | C3: からてチョップ | D3: 空手劈
A4: M003 | B4: DOUBLESLAP | C4: おうふくビンタ | D4: 连环巴掌
A5: M004 | B5: COMET PUNCH | C5: れんぞくパンチ | D5: 连续拳
A6: M005 | B6: MEGA PUNCH | C6: メガトンパンチ | D6: 百万吨重拳
A7: M006 | B7: PAY DAY | C7: ネコにこばん | D7: 聚宝功
A8: M007 | B8: FIRE PUNCH | C8: ほのおのパンチ | D8: 火焰拳
A9: M008 | B9: ICE PUNCH | C9: れいとうパンチ | D9: 冰冻拳
A10: M009 | B10: THUNDERPUNCH | C10: かみなりパンチ | D10: 雷电拳
A11: M010 | B11: SCRATCH | C11: ひっかく | D11: 抓
A12: M011 | B12: VICEGRIP | C12: はさむ | D12: 夹住
A13: M012 | B13: GUILLOTINE | C13: ハサミギロチン | D13: 断头钳
... A252: M251 | B252: BEAT UP | C252: ふくろだたき | D252: 围攻

Sheet 图
A1: --开始------------ | C1: PokeGuide001 | D1: bulbasaur | E1: bulbasaur | F1: =IF(D1<>E1,"已更改","")
A2: SEED | C2: たね | D2: 种子 | E2: 种子 | F2: =IF(D2<>E2,"已更改","")
A3: 2'04 | C3: 0.7 m | D3: 0.7 m | E3: 0.7 m | F3: =IF(D3<>E3,"已更改","")
A4: 15.0 lb | C4: 6.9 kg | D4: 6.9 kg | E4: 6.9 kg | F4: =IF(D4<>E4,"已更改","")
A5: --图鉴------------ | B5: --２页------------ | C5: --图鉴------------------------------ | D5: --图鉴------------------ | E5: --图鉴------------------ | F5: =IF(D5<>E5,"已更改","")
A6: While it is young, | B6: stored in the | C6: うまれて しばらくの あいだ | D6: 刚出生后的一段时间里， | E6: 在出生后的一段时间内， | F6: =IF(D6<>E6,"已更改","") -> 已更改
A7: it uses the | B7: seeds on its back | C7: せなかの タネに つまった | D7: 靠吸收储存在背上种子里的 | E7: 靠吸收储存在背上种子里的 | F7: =IF(D7<>E7,"已更改","")
A8: nutrients that are | B8: in order to grow. | C8: えいようを とって そだつ。 | D8: 营养使自己成长。 | E8: 营养使自己成长。 | F8: =IF(D8<>E8,"已更改","")
F9: =IF(D9<>E9,"已更改","")
A10: --开始------------ | C10: PokeGuide002 | D10: ivysaur | E10: ivysaur | F10: =IF(D10<>E10,"已更改","")
A11: SEED | C11: たね | D11: 种子 | E11: 种子 | F11: =IF(D11<>E11,"已更改","")
A12: 3'03 | C12: 1.0 m | D12: 1.0 m | E12: 1.0 m | F12: =IF(D12<>E12,"已更改","")
A13: 29.0 lb | C13: 13.0 Kg | D13: 13.0 Kg | E13: 13.0 Kg | F13: =IF(D13<>E13,"已更改","")
A14: --图鉴------------ | B14: --２页------------ | C14: --图鉴------------------------------ | D14: --图鉴------------------ | E14: --图鉴------------------ | F14: =IF(D14<>E14,"已更改","")
A15: The bulb on its | B15: The bulb gives off | C15: せなかの つぼみは ようぶんを | D15: 背上的花蕾会在吸取 | E15: 背上的花蕾会在吸取 | F15: =IF(D15<>E15,"已更改","")
A16: back grows as it | B16: a pleasant aroma | C16: きゅうしゅう して ふくらむ。 | D16: 养分后膨胀。开花期间 | E16: 养分后膨胀。开花期间 | F16: =IF(D16<>E16,"已更改","")
A17: absorbs nutrients. | B17: when it blooms. | C17: はなのさくころ いいにおいが する。 | D17: 会发出怡人的香气。 | E17: 会发出怡人的香气。 | F17: =IF(D17<>E17,"已更改","")
F18: =IF(D18<>E18,"已更改","")
A19: --开始------------ | C19: PokeGuide003 | D19: venusaur | E19: venusaur | F19: =IF(D19<>E19,"已更改","")
A20: SEED | C20: たね | D20: 种子 | E20: 种子 | F20: =IF(D20<>E20,"已更改","")
A21: 6'07 | C21: 2.0 m | D21: 2.0 m | E21: 2.0 m | F21: =IF(D21<>E21,"已更改","")
A22: 221.0 lb | C22: 100.0 Kg | D22: 100.0 Kg | E22: 100.0 Kg | F22: =IF(D22<>E22,"已更改","")
A23: --图鉴------------ | B23: --２页------------ | C23: --图鉴------------------------------ | D23: --图鉴------------------ | E23: --图鉴------------------ | F23: =IF(D23<>E23,"已更改","")
A24: As it warms it- | B24: flower petals | C24: たいようの ひかりをあびて からだが | D24: 沐浴阳光让身体变暖的话， | E24: 沐浴阳光让身体变暖的话， | F24: =IF(D24<>E24,"已更改","")
A25: self and absorbs | B25: release a pleasant | C25: あたたまってくると はなびら から | D25: 就会从花瓣散发出 | E25: 就会从花瓣散发出 | F25: =IF(D25<>E25,"已更改","")
A26: the sunlight, its | B26: fragrance. | C26: ここちよくなる かおりが ただよう。 | D26: 令人神清气爽的香味。 | E26: 令人神清气爽的香味。 | F26: =IF(D26<>E26,"已更改","")
F27: =IF(D27<>E27,"已更改","")
A28: --开始------------ | C28: PokeGuide004 | D28: charmander | E28: charmander | F28: =IF(D28<>E28,"已更改","")
A29: LIZARD | C29: とかげ | D29: 蜥蜴 | E29: 蜥蜴 | F29: =IF(D29<>E29,"已更改","")
A30: 2'00 | C30: 0.6 m | D30: 0.6 m | E30: 0.6 m | F30: =IF(D30<>E30,"已更改","")
A31: 19.0 lb | C31: 8.5 Kg | D31: 8.5 Kg | E31: 8.5 Kg | F31: =IF(D31<>E31,"已更改","")
A32: --图鉴------------ | B32: --２页------------ | C32: --图鉴------------------------------ | D32: --图鉴------------------ | E32: --图鉴------------------ | F32: =IF(D32<>E32,"已更改","")
A33: If it's healthy, | B33: will burn vigor- | C33: しっぽの さきの ほのおは | D33: 在精力充沛时，在尾巴尖端 | E33: 在精力充沛时， | F33: =IF(D33<>E33,"已更改","") -> 已更改
A34: the flame on the | B34: ously, even if it | C34: げんきなら すこしくらい ぬれても | D34: 旺盛燃烧的火苗即使沾了 | E34: 尾巴尖端旺盛燃烧的火苗 | F34: =IF(D34<>E34,"已更改","") -> 已更改
A35: tip of its tail | B35: gets a bit wet. | C35: きえることなく もえさかる。 | D35: 少量的水也不会熄灭。 | E35: 即使沾了点水也不会熄灭。 | F35: =IF(D35<>E35,"已更改","") -> 已更改
F36: =IF(D36<>E36,"已更改","")
A37: --开始------------ | C37: PokeGuide005 | D37: charmeleon | E37: charmeleon | F37: =IF(D37<>E37,"已更改","")
A38: FLAME | C38: かえん | D38: 火焰 | E38: 火焰 | F38: =IF(D38<>E38,"已更改","")
A39: 3'07 | C39: 1.1 m | D39: 1.1 m | E39: 1.1 m | F39: =IF(D39<>E39,"已更改","")
A40: 42.0 lb | C40: 19.0 Kg | D40: 19.0 Kg | E40: 19.0 Kg | F40: =IF(D40<>E40,"已更改","")
...

Sheet 其
A1: |-编号---- | B1: |-英文---- | C1: |-日文---- | D1: |-翻译---- | E1: |-注释---- | F1: |-跳过----
A2: O001 | B2: ELM | C2: ウツギ | D2: 空木
A3: O002 | B3: EARL | C3: ジョバンニ | D3: 初始
A4: O003 | B4: KURT | C4: ガンテツ | D4: 钢铁
A5: O004 | B5: MOM | C5: ママ | D5: 妈妈
A6: O005 | B6: BUENA | C6: アオイ | D6: 葵妍
A7: O006 | B7: MR.#MON | C7: ポケモンじいさん | D7: 宝可梦爷爷
A8: O007 | B8: MARY | C8: クルミ | D8: 胡桃 | E8: 大木讲座
A9: O008 | B9: LILY | C9: リリス | D9: 莉莉丝 | E9: 那城这人 对红；朱顶红
A10: O009 | B10: REED | C10: ツゲ | D10: 阿植 | E10: 幸运频道
A11: O010 | B11: BEN | C11: セージ | D11: 靖史 | E11: 城都音乐 鼠尾草
A12: O011 | B12: FERN | C12: コージ | D12: 浩史 | E12: 关都音乐 鼠麴草
A13: O013 | B13: SILKTREE | C13: ネムノキ | D13: 合欢
A14: O014 | B14: MONICA | C14: ツキコ | D14: 星琪一
A15: O015 | B15: TUSCANY | C15: ヒコ | D15: 星琪二
A16: O016 | B16: WESLEY | C16: ミズオ | D16: 星祺三
A17: O017 | B17: ARTHUR | C17: モクオ | D17: 星祺四
A18: O018 | B18: FRIEDA | C18: カネコ | D18: 星琪五
A19: O019 | B19: SANTOS | C19: ツチオ | D19: 星祺六
A20: O020 | B20: SUNNY | C20: ニチオ | D20: 星祺天
A21: O021 | B21: MOVE DELETER | C21: わすれオヤジ | D21: 遗忘大叔 | E21: 忘记大叔 / 招式遗忘大叔
A22: O022 | B22: DUDE | C22: おにいさん | D22: 小哥
A23: O023 | B23: Master of the Dragon Tamer clan | C23: ドラゴンつかいいちぞくの長老さま | D23: 龙之长老 | E23: 根本无法对照，随便填写一下
A24: O024 | B24: MASTER | C24: ちょうろう | D24: 长老 | E24: MASTER全大写基本能对上长老（除了大师球对不上）
A25: O025 | B25: OAK | C25: オーキド | D25: 大木
A26: O026 | B26: DAISY | C26: ナナミ | D26: 奈奈美
A27: O027 | B27: GIOVANNI | C27: サカキ | D27: 坂木
A28: O028 | B28: LORELEI | C28: カンナ | D28: 科拿 | E28: 未出现
A29: O030 | B29: AGATHA | C29: キクコ | D29: 菊子
A30: O032 | B30: BILL | C30: マサキ | D30: 正辉
A31: O033 | B31: MR.FUJI | C31: フジろうじん | D31: 富士老人
A32: O034 | B32: FUJI | C32: フジ | D32: 富士
A33: O035 | B33: BAOBA | C33: バオバ | D33: 巴奥巴 | E33: 未出现
A34: O036 | B34: COPYCAT | C34: モノマネむすめ | D34: 模仿少女 | E34: Mimic Girl的写法不知道哪里来的
A35: O037 | B35: NAME RATER | C35: せいめいはんだんし | D35: 姓名鉴定师
A36: O038 | B36: type | C36: タイプ | D36: 属性
A37: O039 | B37: normal | C37: ノーマルタイプ | D37: 一般 | E37: 英文版小写，或者是normal-type
A38: O040 | B38: fire | C38: ほのおタイプ | D38: 火
A39: O041 | B39: water | C39: みずタイプ | D39: 水
A40: O042 | B40: electric | C40: でんきタイプ | D40: 电
...

Sheet 文1
A1: |---英文---------+ | C1: |---日文-------------------------+ | E1: |---翻译--------------+----------+ | H1: |---提词---------+ | I1: |---注释---------+ | J1: msg_heal_11_common
A2: Good morning! | C2: おはよう ございます！ | E2: 早上好！
A3: Welcome to our | C3: ポケモン センター です！ | E3: 这里是宝可梦中心！
A4: #MON CENTER.
A7: |---英文---------+ | C7: |---日文-------------------------+ | E7: |---翻译--------------+----------+ | H7: |---提词---------+ | I7: |---注释---------+ | J7: msg_heal_12_common
A8: Hello! | C8: こんにちは！ | E8: 你好！
A9: Welcome to our | C9: ポケモン センター です！ | E9: 这里是宝可梦中心！
A10: #MON CENTER.
A13: |---英文---------+ | C13: |---日文-------------------------+ | E13: |---翻译--------------+----------+ | H13: |---提词---------+ | I13: |---注释---------+ | J13: msg_heal_13_common
A14: Good evening! | C14: おそくまで おつかれさまです！ | E14: 坚持到这么晚，辛苦了！
A15: You're out late. | C15: ポケモン センター です！ | E15: 这里是宝可梦中心！
A17: Welcome to our
A18: #MON CENTER.
A21: |---英文---------+ | C21: |---日文-------------------------+ | E21: |---翻译--------------+----------+ | H21: |---提词---------+ | I21: |---注释---------+ | J21: msg_heal_11_01_common
A22: Good morning! | C22: おはよう ございます！ | E22: 早上好！
A24: This is the #- | C24: ポケモンコミュニケーションセンター | E24: 欢迎光临
A25: MON COMMUNICATION | C25: へ ようこそ！ | E25: 宝可梦对话中心！
A27: CENTER--or the
A28: #COM CENTER.
A31: |---英文---------+ | C31: |---日文-------------------------+ | E31: |---翻译--------------+----------+ | H31: |---提词---------+ | I31: |---注释---------+ | J31: msg_heal_12_01_common
A32: Hello! | C32: こんにちは！ | E32: 你好！
A34: This is the #- | C34: ポケモンコミュニケーションセンター | E34: 欢迎光临
A35: MON COMMUNICATION | C35: へ ようこそ！ | E35: 宝可梦对话中心！
A37: CENTER--or the
A38: #COM CENTER.
A41: |---英文---------+ | C41: |---日文-------------------------+ | E41: |---翻译--------------+----------+ | H41: |---提词---------+ | I41: |---注释---------+ | J41: msg_heal_13_01_common
A42: Good to see you | C42: おそくまで おつかれさまです！ | E42: 坚持到这么晚，辛苦了！
A43: working so late.
C44: ポケモンコミュニケーションセンター | E44: 欢迎来到
A45: This is the #- | C45: へ ようこそ！ | E45: 宝可梦对话中心！
A46: MON COMMUNICATION
A48: CENTER--or the
A49: #COM CENTER.
A52: |---英文---------+ | C52: |---日文-------------------------+ | E52: |---翻译--------------+----------+ | H52: |---提词---------+ | I52: |---注释---------+ | J52: msg_heal_01_common
A53: We can heal your | C53: ここでは ポケモンの | E53: 这里将会为您
A54: #MON to perfect | C54: たいりょく かいふくを します！ | E54: 回复宝可梦的体力！
A55: health.
C56: あなたの ポケモンを | E56: 要让你的宝可梦，
A57: Shall we heal your | C57: やすませて あげますか？ | E57: 休息一下吗？
A58: #MON?
...

Sheet 文2
A1: |---英文---------+ | C1: |---日文-------------------------+ | E1: |---翻译--------------+----------+ | H1: |---提词---------+ | I1: |---注释---------+ | J1: msg_bird04_01_d27r0103
A2: Why are you here? | C2: きみは なんなんだ？ | E2: 你是来干嘛的？
A3: Are you just going | C3: おみまいか？ ひやかしか？ | E3: 探望？闲逛？
C4: ひやかしなら かえってもらうよ！ | E4: 闲逛的话还是回去吧！
A5: to gawk? I suggest
A6: that you leave!
A9: |---英文---------+ | C9: |---日文-------------------------+ | E9: |---翻译--------------+----------+ | H9: |---提词---------+ | I9: |---注释---------+ | J9: msg_bird04_02_d27r0103
A10: You really are | C10: ほんき だね | E10: 不是来玩啊……
A11: concerned… | C11: おみまい するんだね | E11: 真的是来探望呢。
A14: |---英文---------+ | C14: |---日文-------------------------+ | E14: |---翻译--------------+----------+ | H14: |---提词---------+ | I14: |---注释---------+ | J14: msg_bird04_03_d27r0103
A15: How the heck do | C15: どうやって うえに のぼるんだ？ | E15: 顶层要怎么走啊？
A16: you go up? | C16: おみまいに いきたいのに | E16: 本来想去探望一下的，
C17: いけなくて こまってるんだよ | E17: 却找不到路，头疼。
A18: I want to visit
A19: the sick #MON,
A21: but I can't get up
A22: there…
A25: |---英文---------+ | C25: |---日文-------------------------+ | E25: |---翻译--------------+----------+ | H25: |---提词---------+ | I25: |---注释---------+ | J25: msg_sailor03_01_d27r0103
A26: Sailors are both | C26: うみのおとこは つよさと やさしさ | E26: 海上男儿既强大
A27: kind and strong. | C27: その ２つを かねそなえている | E27: 又不失温柔。
A28: How about you? | C28: きみは どうなんだ？ | E28: 你又是哪种人呢？
A31: |---英文---------+ | C31: |---日文-------------------------+ | E31: |---翻译--------------+----------+ | H31: |---提词---------+ | I31: |---注释---------+ | J31: msg_sailor03_02_d27r0103
A32: You are both kind | C32: きみの たたかいかた | E32: 你的战斗方式
A33: and strong… | C33: つよさと やさしさが かんじられる | E33: 温柔而强大呢。
A36: |---英文---------+ | C36: |---日文-------------------------+ | E36: |---翻译--------------+----------+ | H36: |---提词---------+ | I36: |---注释---------+ | J36: msg_sailor03_03_d27r0103
A37: Every time I come | C37: アサギに もどるたび | E37: 只要我回到浅葱市，
A38: back to OLIVINE, I | C38: ポケモンジムに よってたのだが…… | E38: 必定会去一趟道馆。
A39: visit the GYM.
C40: ジムリーダーの つかう ポケモンの | E40: 馆主使用的宝可梦属性 | H40: =_xlfn.TEXTJOIN(":",TRUE,类!C2,类!D2) -> ジムリーダー:道馆馆主
A41: The GYM LEADER's | C41: タイプが いつのまにか かわってたよ | E41: 似乎和以前不太一样…… | H41: =_xlfn.TEXTJOIN(":",TRUE,其!C36,其!D36) -> タイプ:属性
A42: #MON type has
A44: changed without me
A45: noticing.
A48: |---英文---------+ | C48: |---日文-------------------------+ | E48: |---翻译--------------+----------+ | H48: |---提词---------+ | I48: |---注释---------+ | J48: msg_gentle01_01_d27r0103
A49: I travel the world | C49: わたしは せかいを たびして | E49: 我周游世界，
A50: to train my #- | C50: ポケモンを きたえている | E50: 以此来锻炼宝可梦。
A51: MON. I wish to | C51: ちょっと しょうぶ してもらいますぞ | E51: 来和我对战吧！
A52: battle with you.
A55: |---英文---------+ | C55: |---日文-------------------------+ | E55: |---翻译--------------+----------+ | H55: |---提词---------+ | I55: |---注释---------+ | J55: msg_gentle01_02_d27r0103
A56: …sigh… I must | C56: はあ…… | E56: 哎……
...

Sheet 文3
A1: |---英文---------+ | C1: |---日文-------------------------+ | E1: |---翻译--------------+----------+ | H1: |---提词---------+ | I1: |---注释---------+ | J1: NoEggMSG_000_Itemmain
A2: An EGG can't hold | C2: タマゴには | E2: 无法让蛋 | H2: =_xlfn.TEXTJOIN(":",TRUE,宝!C254,宝!D254) -> タマゴ:蛋
A3: an item. | C3: もたせることが できません！ | E3: 携带道具！
A6: |---英文---------+ | C6: |---日文-------------------------+ | E6: |---翻译--------------+----------+ | H6: |---提词---------+ | I6: |---注释---------+ | J6: NoItemMSG_001_Itemmain
A7: No items. | C7: もっていません | E7: 没有携带任何道具。
A10: |---英文---------+ | C10: |---日文-------------------------+ | E10: |---翻译--------------+----------+ | H10: |---提词---------+ | I10: |---注释---------+ | J10: TrashCountMSG_002_Itemmain
A11: Throw away how | C11: いくつ すてますか？ | E11: 要丢弃多少个？
A12: many?
A15: |---英文---------+ | C15: |---日文-------------------------+ | E15: |---翻译--------------+----------+ | H15: |---提词---------+ | I15: |---注释---------+ | J15: ReconfirmMSG_003_Itemmain
A16: Throw away 【1】 | C16: 【0】を 【1】こ | E16: 丢弃【1】个【0】， | J16: text_ram wStringBuffer2
A17: 【0】(S)? | C17: すててもよろしいですか？ | E17: 可以吗？ | J17: text_decimal wItemQuantityChange, 1, 2
A20: |---英文---------+ | C20: |---日文-------------------------+ | E20: |---翻译--------------+----------+ | H20: |---提词---------+ | I20: |---注释---------+ | J20: TrashedMSG_004_Itemmain
A21: Threw away | C21: 【0】を | E21: 【0】被 | J21: text_ram wStringBuffer2
A22: 【0】(S). | C22: すてました！ | E22: 丢弃了！
A25: |---英文---------+ | C25: |---日文-------------------------+ | E25: |---翻译--------------+----------+ | H25: |---提词---------+ | I25: |---注释---------+ | J25: InpossibleMSG_005_Itemmain
A26: OAK: <PLAYER>! | C26: オーキドの ことば…… | E26: 大木博士说过…… | H26: =_xlfn.TEXTJOIN(":",TRUE,其!C25,其!D25) -> オーキド:大木
A27: This isn't the | C27: <PLAYER>よ！ こういうものには | E27: <PLAYER>！这种东西
A28: time to use that! | C28: つかいどきが あるのじゃ！ | E28: 是要看场合来用的啊！
A31: |---英文---------+ | C31: |---日文-------------------------+ | E31: |---翻译--------------+----------+ | H31: |---提词---------+ | I31: |---注释---------+ | J31: NoMonsMSG_006_Itemmain
A32: You don't have a | C32: ポケモンを もっていません！ | E32: 没有同行宝可梦！
A33: #MON!
A36: |---英文---------+ | C36: |---日文-------------------------+ | E36: |---翻译--------------+----------+ | H36: |---提词---------+ | I36: |---注释---------+ | J36: EntryMSG_007_Itemmain
A37: Registered the | C37: 【0】を | E37: 将【0】 | J37: text_ram wStringBuffer2
A38: 【0】. | C38: べんりボタンに とうろくした！ | E38: 添加到了快捷键！ | I38: 添加到了便利键！
A41: |---英文---------+ | C41: |---日文-------------------------+ | E41: |---翻译--------------+----------+ | H41: |---提词---------+ | I41: |---注释---------+ | J41: CannotEntryMSG_008_Itemmain
A42: You can't register | C42: そのどうぐは | E42: 那个道具
A43: that item. | C43: とうろくできません！ | E43: 无法被添加！
A46: |---英文---------+ | C46: |---日文-------------------------+ | E46: |---翻译--------------+----------+ | H46: |---提词---------+ | I46: |---注释---------+ | J46: ExchangeMSG_009_Itemmain
A47: Where should this | C47: どこに | E47: 要移动
A48: be moved to? | C48: いどう しますか？ | E48: 到哪里吗？
A51: |---英文---------+ | C51: |---日文-------------------------+ | E51: |---翻译--------------+----------+ | H51: |---提词---------+ | I51: |---注释---------+ | J51: BattleCannotEntry_010_Itemmain
A55: |---英文---------+ | C55: |---日文-------------------------+ | E55: |---翻译--------------+----------+ | H55: |---提词---------+ | I55: |---注释---------+ | J55: BattleCannotUseMS_011_Itemmain
A56: You can't use it | C56: せんとう ちゅうは | E56: 战斗中
A57: in a battle. | C57: できません！ | E57: 不能使用！
A60: |---英文---------+ | C60: |---日文-------------------------+ | E60: |---翻译--------------+----------+ | H60: |---提词---------+ | I60: |---注释---------+ | J60: anata_msg_000_Kojindat
A61: Are you a boy? | C61: あなたは おとこのこ ですか？ | E61: 你是男孩吗？
A62: Or are you a girl? | C62: それとも おんなのこ ですか？ | E62: 还是女孩呢？
A65: |---英文---------+ | C65: |---日文-------------------------+ | E65: |---翻译--------------+----------+ | H65: |---提词---------+ | I65: |---注释---------+ | J65: seikou_msg_000_Kougeki
A66: <USER>'s | C66: <USER>の | E66: <USER>的 | J66: text_ram wStringBuffer2
A67: 【0】 | C67: 【0】が | E67: 【0】
...

Sheet 文4
A1: |---英文---------+ | C1: |---日文-------------------------+ | E1: |---翻译--------------+----------+ | H1: |---提词---------+ | I1: |---注释---------+ | J1: msg_oldwoman_01_r05r0401
A2: Eeyaaaah! | C2: きえーーーいっ！ | E2: 消失——吧！
A4: I sense a sinister | C4: おぬしに ふきつな カゲが | E4: 有个不吉利的影子
A5: shadow hovering | C5: とりついて おるうっ！ | E5: 附在施主身上！
A6: over you. | C6: これを もっていくが よい！ | E6: 请你带上这个！
A8: Take this to ward
A9: it off!
A12: |---英文---------+ | C12: |---日文-------------------------+ | E12: |---翻译--------------+----------+ | H12: |---提词---------+ | I12: |---注释---------+ | J12: msg_oldwoman_02_r05r0401
A13: You were in mortal | C13: あぶないところ じゃった！ | E13: 真是好险啊！
A14: danger, but you | C14: これで あんしんじゃ！ | E14: 这下就能放心了！
A15: are protected now.
A18: |---英文---------+ | C18: |---日文-------------------------+ | E18: |---翻译--------------+----------+ | H18: |---提词---------+ | I18: |---注释---------+ | J18: msg_womana_00_r05r0401
A19: My grandma is into | C19: うちの おばあちゃん | E19: 我家的奶奶呀，
A20: warding off what | C20: おはらいに こってるのよ | E20: 一直很热衷于驱邪。
C21: ごめんね おどろかせちゃって | E21: 抱歉啊，让你受惊了。
A22: she believes to be
A23: evil spirits.
A25: I'm sorry that she
A26: startled you.
A29: |---英文---------+ | C29: |---日文-------------------------+ | E29: |---翻译--------------+----------+ | H29: |---提词---------+ | I29: |---注释---------+ | J29: msg_middlem_00_r06
A30: The road is closed | C30: はつでんしょの じこが | E30: 在发电厂的事故 | H30: =_xlfn.TEXTJOIN(":",TRUE,城!C19,城!D19) -> はつでんしょ:发电厂
A31: until the problem | C31: かいけつ するまで | E31: 得到解决之前，
C32: つうこうきんし なんだって！ | E32: 这里禁止通行！
A33: at the POWER PLANT
A34: is solved.
A37: |---英文---------+ | C37: |---日文-------------------------+ | E37: |---翻译--------------+----------+ | H37: |---提词---------+ | I37: |---注释---------+ | J37: msg_sign01_00_r06
A38: UNDERGROUND PATH | C38: ここから ちかつうろ | E38: 前方是地下通道 | H38: =_xlfn.TEXTJOIN(":",TRUE,城!C101,城!D101) -> ちかつうろ:地下通道
C39: ハナダシティ …… クチバシティ | E39: 华蓝市 <……> 枯叶市 | H39: =_xlfn.TEXTJOIN(" ",TRUE,_xlfn.TEXTJOIN(":",TRUE,城!C31,城!D31),_xlfn.TEXTJOIN(":",TRUE,城!C33,城!D33)) -> ハナダシティ:华蓝市 クチバシティ:枯叶市
A40: CERULEAN CITY -
A41: VERMILION CITY
A44: |---英文---------+ | C44: |---日文-------------------------+ | E44: |---翻译--------------+----------+ | H44: |---提词---------+ | I44: |---注释---------+ | J44: msg_lovem_13_01_r06
A45: My PHANPY is the | C45: だから わたしの ゴマゾウちゃんが | E45: 所以说我的小小象 | H45: =_xlfn.TEXTJOIN(":",TRUE,宝!C232,宝!D232) -> ゴマゾウ:小小象
A46: cutest in the | C46: せかいで １ばん かわいいん です！ | E46: 是世界第1可爱！
A47: world.
A50: |---英文---------+ | C50: |---日文-------------------------+ | E50: |---翻译--------------+----------+ | H50: |---提词---------+ | I50: |---注释---------+ | J50: msg_lovem_13_02_r06
A51: My PHANPY! | C51: わたしの ゴマゾウちゃんがー！ | E51: 我的小小象啊——！ | H51: =_xlfn.TEXTJOIN(":",TRUE,宝!C232,宝!D232) -> ゴマゾウ:小小象
A54: |---英文---------+ | C54: |---日文-------------------------+ | E54: |---翻译--------------+----------+ | H54: |---提词---------+ | I54: |---注释---------+ | J54: msg_lovem_13_03_r06
A55: Look how adorable | C55: みてくださいよ この | E55: 你一定要看一下！
A56: my PHANPY acts! | C56: ゴマゾウちゃんの あまえた しぐさ！ | E56: 我家小小象撒娇的样子！ | H56: =_xlfn.TEXTJOIN(":",TRUE,宝!C232,宝!D232) -> ゴマゾウ:小小象
A58: Isn't it cute | C58: もう かわいくて かわいくて | E58: 真是可爱得不得了！
...

Sheet 文5
A1: |---英文---------+ | C1: |---日文-------------------------+ | E1: |---翻译--------------+----------+ | H1: |---提词---------+ | I1: |---注释---------+ | J1: msg_tree_01_r36
A2: It's a weird tree. | C2: おかしな き だ！ | E2: 有棵奇怪的树！
A3: Use SQUIRTBOTTLE? | C3: ゼニガメじょうろを つかいますか？ | E3: 要使用杰尼龟喷壶吗？ | H3: =_xlfn.TEXTJOIN(":",TRUE,道!C176,道!D176) -> ゼニガメじょうろ:杰尼龟喷壶
A6: |---英文---------+ | C6: |---日文-------------------------+ | E6: |---翻译--------------+----------+ | H6: |---提词---------+ | I6: |---注释---------+ | J6: msg_tree_02_r36
A7: <PLAYER> used the | C7: <PLAYER>は | E7: <PLAYER>使用了
A8: SQUIRTBOTTLE. | C8: ゼニガメじょうろを つかった！ | E8: 杰尼龟喷壶！ | H8: =_xlfn.TEXTJOIN(":",TRUE,道!C176,道!D176) -> ゼニガメじょうろ:杰尼龟喷壶
A11: |---英文---------+ | C11: |---日文-------------------------+ | E11: |---翻译--------------+----------+ | H11: |---提词---------+ | I11: |---注释---------+ | J11: msg_tree_03_r36
A12: The weird tree | C12: おかしな きは | E12: 奇怪的树好像很反感
A13: doesn't like the | C13: ゼニガメじょうろを いやがってる！ | E13: 杰尼龟喷壶！ | H13: =_xlfn.TEXTJOIN(":",TRUE,道!C176,道!D176) -> ゼニガメじょうろ:杰尼龟喷壶
A14: SQUIRTBOTTLE!
C15: おかしな きが おそいかかってきた！ | E15: 奇怪的树扑过来了！
A16: The weird tree
A17: attacked!
A20: |---英文---------+ | C20: |---日文-------------------------+ | E20: |---翻译--------------+----------+ | H20: |---提词---------+ | I20: |---注释---------+ | J20: msg_saki_01_r36
A21: I'm the FLOWER | C21: あたし フラワーショップの サキ | E21: 我是花店的绽芳。
A22: SHOP's FLORIA!
C23: ねーねー きいて きいて！ | E23: 听我说，听我说！
A24: Listen, listen!
C25: うごく きに みずを かけて みたら | E25: 我试着给会动的树浇水，
A26: When I sprinkled | C26: おどろいて とびあがったの！ | E26: 它居然吓了一跳！
A27: water on that
C28: きっと しょうたいは ポケモンなのよ | E28: 我猜它肯定是宝可梦！
A29: wiggly tree, it
A30: jumped right up! | C30: もっと みずを かければ おどろいて | E30: 再多浇点水吓吓它，
C31: しょうたいを あらわす はずよ！ | E31: 它一定会原形毕露！
A32: It just has to be
A33: a #MON. | C33: そうだ！ | E33: 对了！
C34: おねえちゃんに このことを はなして | E34: 我要把这件事告诉姐姐，
A35: I bet it would be | C35: じょうろを かして もらおーっと！ | E35: 让她把喷壶借给我！
A36: shocked out of its
A38: disguise if you
A39: soaked it!
A41: I know! I'll tell
A42: my sis and borrow
A43: her water bottle!
A46: |---英文---------+ | C46: |---日文-------------------------+ | E46: |---翻译--------------+----------+ | H46: |---提词---------+ | I46: |---注释---------+ | J46: msg_saki_02_r36
A47: When I told my sis | C47: うちの おねえちゃんに | E47: 我跟我姐姐讲了
A48: about the jiggly | C48: うごく きの はなしを したら | E48: 那棵会动的树的事情，
C49: あぶないから やめなさい だって！ | E49: 她却说太危险了别管它！
A50: tree, she said
...

Sheet 文6
A1: |---英文---------+ | C1: |---日文-------------------------+ | E1: |---翻译--------------+----------+ | H1: |---提词---------+ | I1: |---注释---------+ | J1: msg_matisu_01_t06r0701
A2: SURGE: Hey, you | C2: マチス『ヘーイ！ | E2: 马志士：Hey！ | H2: =_xlfn.TEXTJOIN(":",TRUE,训!C35,训!D35) -> マチス:马志士
A3: little tyke! | C3: プア リトル キッド！ | E3: Poor little kid！
A5: I have to hand it | C5: ミーに たたかいを いどむなんて | E5: 居然想向me发起挑战，
A6: to you. It may not | C6: ユーは みのほどしらず！ | E6: You真是不知天高地厚！
C7: ミーの エレクトリック ポケモン | E7: Me的electric宝可梦，
A8: be very smart to | C8: ナンバー ワン ねー！ | E8: 简直number one！
A9: challenge me, but
A10: it takes guts! | C10: せんじょうじゃ まけたこと | E10: Me在战场上
C11: アリマセーン！！ | E11: 从来没输过！！
A12: When it comes to
A13: electric #MON, | C13: ユーも てきの ソルジャー みたく | E13: 我要让you浑身麻麻的，
A14: I'm number one! | C14: びりびり シビレさせてあげるよ！ | E14: 就像敌方soldier那样！
A16: I've never lost on
A17: the battlefield.
A19: I'll zap you just
A20: like I did my
A21: enemies in war!
A24: |---英文---------+ | C24: |---日文-------------------------+ | E24: |---翻译--------------+----------+ | H24: |---提词---------+ | I24: |---注释---------+ | J24: msg_matisu_02_t06r0701
A25: SURGE: Arrrgh! | C25: マチス『オー ノー！ | E25: 马志士：Oh no！ | H25: =_xlfn.TEXTJOIN(":",TRUE,训!C35,训!D35) -> マチス:马志士
A26: You are strong! | C26: ユー は ストロング！ | E26: You真是strong！
A28: OK, kid. You get | C28: オッケー！ | E28: Ok！
A29: THUNDERBADGE! | C29: オレンジバッジ やるヨ！ | E29: 橙色徽章就给you了！
A32: |---英文---------+ | C32: |---日文-------------------------+ | E32: |---翻译--------------+----------+ | H32: |---提词---------+ | I32: |---注释---------+ | J32: msg_matisu_03_t06r0701
A33: <PLAYER> received | C33: <PLAYER>は マチスから | E33: <PLAYER>从马志士那里 | H33: =_xlfn.TEXTJOIN(":",TRUE,训!C35,训!D35) -> マチス:马志士
A34: THUNDERBADGE. | C34: オレンジバッジを もらった！ | E34: 得到了橙色徽章！
A37: |---英文---------+ | C37: |---日文-------------------------+ | E37: |---翻译--------------+----------+ | H37: |---提词---------+ | I37: |---注释---------+ | J37: msg_matisu_04_t06r0701
A38: SURGE: THUNDER- | C38: マチス『オレンジバッジ もってると | E38: 马志士：有了橙色徽章， | H38: =_xlfn.TEXTJOIN(":",TRUE,训!C35,训!D35) -> マチス:马志士
A39: BADGE increases | C39: ユーの ポケモン スピード アップ！ | E39: You的宝可梦
A40: #MON's speed. | E40: 就会speed up！
C41: ミーに かった あかし ネー！
A42: Consider it proof | C42: たいせつ する グッド！ | E42: 这是战胜me的证明！
A43: that you defeated | E43: You要好好珍惜！
A45: me. You wear it
A46: proudly, hear?
A49: |---英文---------+ | C49: |---日文-------------------------+ | E49: |---翻译--------------+----------+ | H49: |---提词---------+ | I49: |---注释---------+ | J49: msg_matisu_05_t06r0701
A50: SURGE: Hey, kid! | C50: マチス『ヘイ！ ユー！ | E50: 马志士：Hey，you！ | H50: =_xlfn.TEXTJOIN(":",TRUE,训!C35,训!D35) -> マチス:马志士
A51: Still slugging and | C51: がんばって ますかー？ | E51: 还在继续努力吧？
A52: chugging away?
C53: ミーと ポケモンも | E53: Me和宝可梦们
...

Sheet 文7
A1: |---英文---------+ | C1: |---日文-------------------------+ | E1: |---翻译--------------+----------+ | H1: |---提词---------+ | I1: |---注释---------+ | J1: msg_manb_01_t24r0201
A2: I, I'm in shock! | C2: な なんてことだ…… | E2: 这、这算什么啊……
A4: A guy about your | C4: きみと おなじくらいの としごろで | E4: 有个和你年纪差不多、
A5: age with piercing | C5: めつきが するどくて | E5: 目光凶狠、
C6: かみのけ ながくて | E6: 长发飘飘、
A7: eyes and long hair | C7: なんだか こわそうな しょうねんに | E7: 样子有些可怕的少年
A8: came in. | C8: だいじな ポケモンを とられたよ！ | E8: 把我宝贵的宝可梦抢走了！
A10: He scared me into | C10: てもとに １ぴき のこっているけど | E10: 我身边只剩1只了，
A11: giving him my | C11: また おそわれたら どうしよう…… | E11: 要是再次遇袭的话……
A12: prized #MON!
C13: きみ つよそうだな | E13: 你看起来挺强的啊。
A14: I still have one | C14: しばらく ポケモン あずかってよ！ | E14: 暂时帮我保管宝可梦吧！
A15: left, but what if
A16: he comes back?
A18: You look strong.
A19: Could you look
A21: after my #MON
A22: for a while?
A25: |---英文---------+ | C25: |---日文-------------------------+ | E25: |---翻译--------------+----------+ | H25: |---提词---------+ | I25: |---注释---------+ | J25: msg_manb_02_t24r0201
A26: Oh, thank you! | C26: じゃ じゃあ たのむ！ | E26: 那就定了，拜托你了！
C27: だいじに してやってくれよ | E27: 一定要好好对它！
A28: Take good care of
A29: it, please!
A32: |---英文---------+ | C32: |---日文-------------------------+ | E32: |---翻译--------------+----------+ | H32: |---提词---------+ | I32: |---注释---------+ | J32: msg_manb_03_t24r0201
A33: <PLAYER> received a | C33: <PLAYER>は マニアから | E33: <PLAYER>从狂热迷
A34: #MON. | C34: ポケモンを あずかった！ | E34: 那里接管了宝可梦！
A37: |---英文---------+ | C37: |---日文-------------------------+ | E37: |---翻译--------------+----------+ | H37: |---提词---------+ | I37: |---注释---------+ | J37: msg_manb_05_t24r0201
A38: Your #MON party | C38: ポケモン いっぱいだよ | E38: 你的宝可梦太多了！
A39: is full.
A42: |---英文---------+ | C42: |---日文-------------------------+ | E42: |---翻译--------------+----------+ | H42: |---提词---------+ | I42: |---注释---------+ | J42: msg_manb_06_t24r0201
A43: Oh, no… What'll | C43: そ そんなあ | E43: 怎、怎么这样……
A44: I do if he comes | C44: また おそわれたら どうしよう | E44: 下次遇袭该怎么办啊？
A45: back?
A48: |---英文---------+ | C48: |---日文-------------------------+ | E48: |---翻译--------------+----------+ | H48: |---提词---------+ | I48: |---注释---------+ | J48: msg_manb_10_t24r0201
A49: Hi! How's my #- | C49: ぼくの ポケモン げんき？ | E49: 我的宝可梦还好吗？
A50: MON?
C51: もう おそわれそうに ないし | E51: 好像不会再遇袭了，
A52: I think I'm safe | C52: ポケモン かえしてほしいんだ | E52: 我希望你把宝可梦还给我。
A53: now, so may I have
A54: it back?
...

Sheet 文8
A1: |---英文---------+ | C1: |---日文-------------------------+ | E1: |---翻译--------------+----------+ | H1: |---提词---------+ | I1: |---注释---------+ | J1: msg_leader08_01_t30r0101
A2: I am CLAIR. | C2: わたしは イブキ！ | E2: 我叫小椿！ | H2: =_xlfn.TEXTJOIN(":",TRUE,训!C9,训!D9) -> イブキ:小椿
A4: The world's best | C4: せかいで いちばんの | E4: 是世界第一
A5: dragon master. | C5: ドラゴンつかい よ | E5: 龙使者。
A7: I can hold my own | C7: じつりょくも ポケモンリーグ | E7: 即使是面对
A8: against even the | C8: してんのうに だって | E8: 联盟里的四天王， | H8: =_xlfn.TEXTJOIN(":",TRUE,类!C12,类!D12) -> してんのう:四天王
C9: まけてなんか ないわよ！ | E9: 凭我的实力也不会输！
A10: #MON LEAGUE's | C10: どう それでも たたかうの？ | E10: 即便如此，你还要挑战吗？
A11: ELITE FOUR.
C12: …… そう わかったわ | E12: ……好吧，我明白了。
A13: Do you still want | C13: じゃ はじめましょう！ | E13: 那就开始吧！
A14: to take me on?
C15: わたしも ジムリーダーとして | E15: 作为道馆馆主， | H15: =_xlfn.TEXTJOIN(":",TRUE,类!C2,类!D2) -> ジムリーダー:道馆馆主
A16: …Fine. | C16: ぜんりょくで あいて してあげる！ | E16: 我会全力应战的！
A17: Let's do it!
A19: As a GYM LEADER,
A20: I will use my full
A22: power against any
A23: opponent!
A26: |---英文---------+ | C26: |---日文-------------------------+ | E26: |---翻译--------------+----------+ | H26: |---提词---------+ | I26: |---注释---------+ | J26: msg_leader08_02_t30r0101
A27: I lost? | C27: この わたしが まけるなんて…… | E27: 我居然输了……
A29: I don't believe | C29: しんじられない | E29: 不敢相信！
A30: it. There must be | C30: なにかの まちがいよ…… | E30: 一定是哪里弄错了……
A31: some mistake…
A34: |---英文---------+ | C34: |---日文-------------------------+ | E34: |---翻译--------------+----------+ | H34: |---提词---------+ | I34: |---注释---------+ | J34: msg_leader08_03_t30r0101
A35: I won't admit | C35: わたしは みとめないわ | E35: 我不承认。
A36: this.
C37: まけて いうのも なんだけど | E37: 虽然输家说这种话不合适，
A38: I may have lost, | C38: あなたの かんがえかた じゃ | E38: 可是以你现在的心态
A39: but you're still | C39: ポケモンリーグに ちょうせん なんて | E39: 根本就没有资格
C40: むり よ | E40: 挑战宝可梦联盟。
A41: not ready for the
A42: #MON LEAGUE. | C42: …… そうだわ！ | E42: ……对了！
A44: I know. You should | C44: この ポケモンジムの うらに | E44: 在这个宝可梦道馆后面
A45: take the dragon | C45: りゅうのあな とよばれる | E45: 有一个洞穴， | H45: =_xlfn.TEXTJOIN(":",TRUE,城!C25,城!D25) -> りゅうのあな:龙穴
A46: user challenge. | C46: ばしょが あるの | E46: 人们称之为龙穴。
A48: Behind this GYM is | C48: ちゅうおうに ほこらが あるから | E48: 龙穴中心处有个祠堂，
A49: a place called | C49: そこへ いきなさい | E49: 你去那里吧。
A50: DRAGON'S DEN.
C51: もし そこで あなたが | E51: 如果你能在那里
...

Sheet 文9
A1: |---英文---------+ | C1: |---日文-------------------------+ | E1: |---翻译--------------+----------+ | H1: |---提词---------+ | I1: |---注释---------+ | J1: msg_middlew01_01_t25r1201
A2: Oh my, your pack | C2: あらあら！ あなた リュックに | E2: 哎呀哎呀！你的背包里 | H2: =_xlfn.TEXTJOIN(":",TRUE,其!C59,其!D59) -> リュック:背包
A3: looks so heavy! | C3: たくさん つめこんで おもそうねえー | E3: 装了许多东西对吧？
A5: Oh! Do you happen | C5: そうだわ！ もしかして あなた | E5: 对了！你有没有
A6: to have something | C6: ブイブイメール っていうの | E6: 叫做伊布信件的道具？ | H6: =_xlfn.TEXTJOIN(":",TRUE,道!C186,道!D186) -> ブイブイメール:伊布信件
A7: named EON MAIL? | C7: もってないかしら？ | E7: 我的女儿说她很想要，
C8: むすめが ほしいって いうのよ | E8: 你能分我一个吗？
A9: My daughter is | C9: ひとつくらい わけて くれるでしょ？
A10: after one.
A12: You can part with
A13: one, can't you?
A16: |---英文---------+ | C16: |---日文-------------------------+ | E16: |---翻译--------------+----------+ | H16: |---提词---------+ | I16: |---注释---------+ | J16: msg_middlew01_02_t25r1201
A17: Give away an EON | C17: ブイブイメールを あげますか？ | E17: 要给出伊布信件吗？ | H17: =_xlfn.TEXTJOIN(":",TRUE,道!C186,道!D186) -> ブイブイメール:伊布信件
A18: MAIL?
A21: |---英文---------+ | C21: |---日文-------------------------+ | E21: |---翻译--------------+----------+ | H21: |---提词---------+ | I21: |---注释---------+ | J21: msg_middlew01_03_t25r1201
A22: Oh, that's great! | C22: ああ たすかった！ | E22: 啊啊，帮大忙了！
A23: Thank you, honey! | C23: あなた ありがとうね | E23: 谢谢你啊。
A25: Here, this is for | C25: もらう ばかりじゃ わるいから | E25: 白拿你的东西也不太好，
A26: you in return! | C26: おれいに これ あげるわよ | E26: 这个就当是回礼了。
A29: |---英文---------+ | C29: |---日文-------------------------+ | E29: |---翻译--------------+----------+ | H29: |---提词---------+ | I29: |---注释---------+ | J29: msg_middlew01_04_t25r1201
A30: My daughter will | C30: むすめも よろこぶわ！ | E30: 我女儿一定会很高兴的！
A31: be delighted!
A34: |---英文---------+ | C34: |---日文-------------------------+ | E34: |---翻译--------------+----------+ | H34: |---提词---------+ | I34: |---注释---------+ | J34: msg_middlew01_05_t25r1201
A35: Oh? You don't have | C35: あら ないの？ ざんねんねえ… | E35: 哎呀，没有吗？真可惜……
A36: one? Too bad.
A39: |---英文---------+ | C39: |---日文-------------------------+ | E39: |---翻译--------------+----------+ | H39: |---提词---------+ | I39: |---注释---------+ | J39: msg_middlew01_06_t25r1201
A40: Oh… Well, another | C40: あら… | E40: 哎呀……
A41: time, then. | C41: じゃあ また こんど ちょうだいね | E41: 那还是下次再说吧。
A44: |---英文---------+ | C44: |---日文-------------------------+ | E44: |---翻译--------------+----------+ | H44: |---提词---------+ | I44: |---注释---------+ | J44: msg_middlew01_07_t25r1201
A45: <PLAYER> gave away | C45: <PLAYER>は | E45: <PLAYER>交出了
A46: the EON MAIL. | C46: ブイブイメールを わたした！ | E46: 伊布信件！ | H46: =_xlfn.TEXTJOIN(":",TRUE,道!C186,道!D186) -> ブイブイメール:伊布信件
A49: |---英文---------+ | C49: |---日文-------------------------+ | E49: |---翻译--------------+----------+ | H49: |---提词---------+ | I49: |---注释---------+ | J49: msg_manb01_01_r40r0201_nm
A50: Are you going to | C50: きみも バトルタワーに いくの？ | E50: 你也要去对战塔吗？ | H50: =_xlfn.TEXTJOIN(":",TRUE,城!C102,城!D102) -> バトルタワー:对战塔
A51: the BATTLE TOWER?
C52: じつは ここだけの はなしだけど | E52: 如果有人赢了很多次，
A53: This is a secret, | C53: たくさん かちぬいた ひとには | E53: 好像会获得礼物呢。
A54: but if you win a | C54: なにか プレゼントが あるらしいよ！ | E54: 我只告诉你一个人哦！ | H54: =_xlfn.TEXTJOIN(":",TRUE,招!C218,招!D218) -> プレゼント:礼物
A56: whole lot, you can
A57: win special gifts.
A60: |---英文---------+ | C60: |---日文-------------------------+ | E60: |---翻译--------------+----------+ | H60: |---提词---------+ | I60: |---注释---------+ | J60: msg_girl_00_t07_nm
...

Sheet 文10
A1: |---英文---------+ | C1: |---日文-------------------------+ | E1: |---翻译--------------+----------+ | H1: |---提词---------+ | I1: |---注释---------+ | J1: msg1_003_Play2 | K1: GS
A2: Trade 【0】 | C2: 【0】 と 【1】 を | E2: 将用【0】 | J2: text_ram wBufferTrademonNickname
A3: for 【1】? | C3: こうかんします | E3: 交换【1】？ | J3: text_ram wStringBuffer1
A5: |---英文---------+ | C5: |---日文-------------------------+ | E5: |---翻译--------------+----------+ | H5: |---提词---------+ | I5: |---注释---------+ | J5: honou_m01 | K5: GS
A6: <TARGET> | C6: <TARGET>は うずの なかに | E6: <TARGET> | I6: 水火漩涡都使用这个文本
A7: was trapped! | C7: とじこめられた！ | E7: 被困在了旋涡之中！
A9: |---英文---------+ | C9: |---日文-------------------------+ | E9: |---翻译--------------+----------+ | H9: |---提词---------+ | I9: |---注释---------+ | J9: msg_telboy_01_common | K9: GS
A10: Wow! You're pretty | C10: ところで つよいね きみ！ | E10: 说起来，你可真强啊！ | I10: 그건 그렇고 강하구나 너!
A11: tough. | C11: よかったら でんわばんごう | E11: 那么你愿不愿意 | I11: 괜찮다면 전화번호
C12: おしえて くれない？ | E12: 把电话号码告诉我呢？ | I12: 가르쳐주지 않을래?
A13: Could I get your
A14: phone number? | C14: また しょうぶ したくなったら | E14: 我下次想和你对战的时候， | I14: 또 승부하고 싶어진다면
C15: でんわ するから | E15: 会给你打电话的。 | I15: 전화할 테니까
A16: I'll call you for
A17: a rematch.
A19: |---英文---------+ | C19: |---日文-------------------------+ | E19: |---翻译--------------+----------+ | H19: |---提词---------+ | I19: |---注释---------+ | J19: msg_telboy_02_common | K19: GS
A20: Register the phone | C20: でんわばんごう | E20: 要添加 | I20: 전화번호
A21: number? | C21: とうろく するかい？ | E21: 电话号码吗？ | I21: 등록하겠니？
A23: |---英文---------+ | C23: |---日文-------------------------+ | E23: |---翻译--------------+----------+ | H23: |---提词---------+ | I23: |---注释---------+ | J23: msg_telboy_04_common | K23: GS
A24: I'll call you if | C24: なにか あったら | E24: 有事情的时候， | I24: 무슨 일 있다면
A25: anything comes up. | C25: でんわ するからね | E25: 我会打电话给你的。 | I25: 전화할 테니까
A27: |---英文---------+ | C27: |---日文-------------------------+ | E27: |---翻译--------------+----------+ | H27: |---提词---------+ | I27: |---注释---------+ | J27: msg_telboy_05_common | K27: GS
A28: Oh, OK… | C28: ま いいか… | E28: 啊，那算了…… | I28: 뭐 좋을대로…
A29: Just talk to me if | C29: とうろく したく なったら | E29: 等你想添加号码的时候， | I29: 등록하고싶어지면
C30: また はなしかけてよ！ | E30: 就来找我搭话吧！ | I30: 다시 말 해줘！
A31: you want to get my
A32: phone number.
A34: |---英文---------+ | C34: |---日文-------------------------+ | E34: |---翻译--------------+----------+ | H34: |---提词---------+ | I34: |---注释---------+ | J34: msg_telboy_06_common | K34: GS
A35: Your phone doesn't | C35: って きみの でんわ | E35: 喂，你的电话存满了， | I35: 어라 네 전화 메모리가
A36: have enough memory | C36: いっぱいで とうろく できないな！ | E36: 无法再添加号码了！ | I36: 가득차서 등록되지 않네！
A37: for more numbers.
A39: |---英文---------+ | C39: |---日文-------------------------+ | E39: |---翻译--------------+----------+ | H39: |---提词---------+ | I39: |---注释---------+ | J39: msg_telboy_07_common | K39: GS
A40: I was waiting for | C40: まってたよ！ | E40: 等着你呢！ | I40: 기다렸다구
A41: you. Let's battle! | C41: それじゃあ しょうぶ しようか！ | E41: 那么，来和我对战吧！ | I41: 그러면 승부하자！
A43: |---英文---------+ | C43: |---日文-------------------------+ | E43: |---翻译--------------+----------+ | H43: |---提词---------+ | I43: |---注释---------+ | J43: msg_telgirl_01_common | K43: GS
A44: Wow, you're good | C44: ところで ポケモン つよいわね！ | E44: 说起来，你的宝可梦真强！ | I44: 그건그렇고 포켓몬이 아주 강하네！
A45: at battling. | C45: よかったら | E45: 那么你愿意 | I45: 괜찮다면
C46: でんわばんごう おしえて？ | E46: 把电话号码告诉我吗？ | I46: 전화번호 가르쳐줄래？
A47: Want to give me
A48: your phone number? | C48: また しょうぶ したくなったら | E48: 我下次想和你对战的时候， | I48: 또 승부하고싶어지면
...

Sheet 标
A1: |---dmap----------- | B1: |---omap----------- | C1: |---dlabel--------- | D1: |---olabel--------- | E1: |---ofname--------- | F1: |---oeom_jp-------- | G1: |---oeom_en--------
A2: data/text/std_text.asm | B2: COMMON | C2: NurseMornText | D2: msg_heal_11_common | E2: script\English\common.mg | F2: EOMeom | G2: EOMeom
A3: data/text/std_text.asm | B3: COMMON | C3: NurseDayText | D3: msg_heal_12_common | E3: script\English\common.mg | F3: EOMeom | G3: EOMeom
A4: data/text/std_text.asm | B4: COMMON | C4: NurseNiteText | D4: msg_heal_13_common | E4: script\English\common.mg | F4: EOMeom | G4: EOMeom
A5: data/text/std_text.asm | B5: COMMON | C5: PokeComNurseMornText | D5: msg_heal_11_01_common | E5: script\English\common.mg | F5: EOMeom | G5: EOMeom | I5: CR
A6: data/text/std_text.asm | B6: COMMON | C6: PokeComNurseDayText | D6: msg_heal_12_01_common | E6: script\English\common.mg | F6: EOMeom | G6: EOMeom | I6: CR
A7: data/text/std_text.asm | B7: COMMON | C7: PokeComNurseNiteText | D7: msg_heal_13_01_common | E7: script\English\common.mg | F7: EOMeom | G7: EOMeom | I7: CR
A8: data/text/std_text.asm | B8: COMMON | C8: NurseAskHealText | D8: msg_heal_01_common | E8: script\English\common.mg | F8: EOMeom | G8: EOMeom
A9: data/text/std_text.asm | B9: COMMON | C9: NurseTakePokemonText | D9: msg_heal_02_common | E9: script\English\common.mg | F9: EOMeom | G9: EOMeom
A10: data/text/std_text.asm | B10: COMMON | C10: NurseReturnPokemonText | D10: msg_heal_03_common | E10: script\English\common.mg | F10: EOMeom | G10: EOMeom
A11: data/text/std_text.asm | B11: COMMON | C11: NurseGoodbyeText | D11: msg_heal_04_common | E11: script\English\common.mg | F11: EOMeom | G11: EOMeom
A12: data/text/std_text.asm | B12: COMMON | C12: NurseSeeYouAgainTextUnused | D12: msg_heal_05_common | E12: script\English\common.mg | F12: EOMeom | G12: EOMeom
A13: data/text/std_text.asm | B13: COMMON | C13: NursePokerusText | D13: msg_heal_10_common | E13: script\English\common.mg | F13: EOMeom | G13: EOMeom
A14: data/text/std_text.asm | B14: COMMON | C14: PokeComNursePokerusText | D14: msg_heal_10_01_common | E14: script\English\common.mg | F14: EOMeom | G14: EOMeom | I14: CR
A15: data/text/std_text.asm | B15: COMMON | C15: DifficultBookshelfText | D15: msg_shelves01_common | E15: script\English\common.mg | F15: EOMeom | G15: EOMeom
A16: data/text/std_text.asm | B16: COMMON | C16: PictureBookshelfText | D16: msg_shelves02_common | E16: script\English\common.mg | F16: EOMeom | G16: EOMeom
A17: data/text/std_text.asm | B17: COMMON | C17: MagazineBookshelfText | D17: msg_shelves03_common | E17: script\English\common.mg | F17: EOMeom | G17: EOMeom
A18: data/text/std_text.asm | B18: COMMON | C18: TeamRocketOathText | D18: msg_shelves04_common | E18: script\English\common.mg | F18: EOMeom | G18: EOMeom
A19: data/text/std_text.asm | B19: COMMON | C19: IncenseBurnerText | D19: msg_butu_common | E19: script\English\common.mg | F19: EOMeom | G19: EOMeom
A20: data/text/std_text.asm | B20: COMMON | C20: MerchandiseShelfText | D20: msg_rack_common | E20: script\English\common.mg | F20: EOMeom | G20: EOMeom
A21: data/text/std_text.asm | B21: COMMON | C21: LookTownMapText | D21: msg_map_common | E21: script\English\common.mg | F21: EOMeom | G21: EOMeom
A22: data/text/std_text.asm | B22: COMMON | C22: WindowText | D22: msg_window_common | E22: script\English\common.mg | F22: EOMeom | G22: EOMeom
A23: data/text/std_text.asm | B23: COMMON | C23: TVText | D23: msg_tv_common | E23: script\English\common.mg | F23: EOMeom | G23: EOMeom
A24: data/text/std_text.asm | B24: COMMON | C24: HomepageText | D24: msg_com_common | E24: script\English\common.mg | F24: EOMeom | G24: EOMeom
A25: data/text/std_text.asm | B25: COMMON | C25: PokemonRadioTextUnused | D25: msg_radio_common | E25: script\English\common.mg | F25: EOMeom | G25: EOMeom
A26: data/text/std_text.asm | B26: COMMON | C26: TrashCanText | D26: msg_trash_common | E26: script\English\common.mg | F26: EOMeom | G26: EOMeom
... A52: data/text/std_text.asm | B52: COMMON | C52: HappinessText1 | D52: msg_friendm_03_common | E52: script\English\common.mg | F52: EOMeom | G52: EOMeom
A53: data/text/std_text.asm | B53: COMMON | C53: RegisteredNumber1Text | D53: msg_telboy_03_common | E53: script\English\common.mg | F53: EOMeom | G53: EOMeom | I53: CR
A54: data/text/std_text.asm | B54: COMMON | C54: RegisteredNumber2Text | D54: msg_telgirl_03_common | E54: script\English\common.mg | F54: EOMeom | G54: EOMeom | I54: CR
A55: data/phone/text/jack_overworld.asm | B55: COMMON | C55: JackAskNumber1Text | D55: msg_telboy01_01_d22r0101 | E55: script\English\common.mg | F55: EOMeom | G55: EOMeom | I55: CR
A56: data/phone/text/jack_overworld.asm | B56: COMMON | C56: JackAskNumber2Text | D56: msg_telboy01_02_d22r0101 | E56: script\English\common.mg | F56: EOMeom | G56: EOMeom | I56: CR
A57: data/phone/text/jack_overworld.asm | B57: COMMON | C57: JackNumberAcceptedText | D57: msg_telboy01_04_d22r0101 | E57: script\English\common.mg | F57: EOMeom | G57: EOMeom | I57: CR
A58: data/phone/text/jack_overworld.asm | B58: COMMON | C58: JackNumberDeclinedText | D58: msg_telboy01_05_d22r0101 | E58: script\English\common.mg | F58: EOMeom | G58: EOMeom | I58: CR
A59: data/phone/text/jack_overworld.asm | B59: COMMON | C59: JackPhoneFullText | D59: msg_telboy01_06_d22r0101 | E59: script\English\common.mg | F59: EOMeom | G59: EOMeom | I59: CR
A60: data/phone/text/jack_overworld.asm | B60: COMMON | C60: JackRematchText | D60: msg_telboy01_07_d22r0101 | E60: script\English\common.mg | F60: EOMeom | G60: EOMeom | I60: CR
A61: data/phone/text/beverly_overworld.asm | B61: COMMON | C61: BeverlyAskNumber1Text | D61: msg_telgirl01_01_d22r0101 | E61: script\English\common.mg | F61: EOMeom | G61: EOMeom | I61: CR
A62: data/phone/text/beverly_overworld.asm | B62: COMMON | C62: BeverlyAskNumber2Text | D62: msg_telgirl01_02_d22r0101 | E62: script\English\common.mg | F62: EOMeom | G62: EOMeom | I62: CR
A63: data/phone/text/beverly_overworld.asm | B63: COMMON | C63: BeverlyNumberAcceptedText | D63: msg_telgirl01_04_d22r0101 | E63: script\English\common.mg | F63: EOMeom | G63: EOMeom | I63: CR
A64: data/phone/text/beverly_overworld.asm | B64: COMMON | C64: BeverlyNumberDeclinedText | D64: msg_telgirl01_05_d22r0101 | E64: script\English\common.mg | F64: EOMeom | G64: EOMeom | I64: CR
... A141: data/phone/text/todd_overworld.asm | B141: COMMON2 | C141: ToddRematchText | D141: msg_telboy01_07_r34 | E141: script\English\common2.mg | F141: EOMeom | G141: EOMeom | I141: CR
...

Sheet Sheet
